<sdf version='1.6'>
  <world name='default'>
    <light name='sun' type='directional'>
      <cast_shadows>1</cast_shadows>
      <pose frame=''>0 0 10 0 -0 0</pose>
      <diffuse>0.8 0.8 0.8 1</diffuse>
      <specular>0.2 0.2 0.2 1</specular>
      <attenuation>
        <range>1000</range>
        <constant>0.9</constant>
        <linear>0.01</linear>
        <quadratic>0.001</quadratic>
      </attenuation>
      <direction>-0.5 0.1 -0.9</direction>
    </light>
    <model name='ground_plane'>
      <static>1</static>
      <link name='link'>
        <collision name='collision'>
          <geometry>
            <plane>
              <normal>0 0 1</normal>
              <size>100 100</size>
            </plane>
          </geometry>
          <surface>
            <contact>
              <collide_bitmask>65535</collide_bitmask>
              <ode/>
            </contact>
            <friction>
              <ode>
                <mu>100</mu>
                <mu2>50</mu2>
              </ode>
              <torsional>
                <ode/>
              </torsional>
            </friction>
            <bounce/>
          </surface>
          <max_contacts>10</max_contacts>
        </collision>
        <visual name='visual'>
          <cast_shadows>0</cast_shadows>
          <geometry>
            <plane>
              <normal>0 0 1</normal>
              <size>100 100</size>
            </plane>
          </geometry>
          <material>
            <script>
              <uri>file://media/materials/scripts/gazebo.material</uri>
              <name>Gazebo/Grey</name>
            </script>
          </material>
        </visual>
        <self_collide>0</self_collide>
        <enable_wind>0</enable_wind>
        <kinematic>0</kinematic>
      </link>
    </model>
    <gravity>0 0 -9.8</gravity>
    <magnetic_field>6e-06 2.3e-05 -4.2e-05</magnetic_field>
    <atmosphere type='adiabatic'/>
    <physics name='default_physics' default='0' type='ode'>
      <max_step_size>0.001</max_step_size>
      <real_time_factor>1</real_time_factor>
      <real_time_update_rate>1000</real_time_update_rate>
    </physics>
    <scene>
      <ambient>0.4 0.4 0.4 1</ambient>
      <background>0.7 0.7 0.7 1</background>
      <shadows>1</shadows>
    </scene>
    <audio>
      <device>default</device>
    </audio>
    <wind/>
    <spherical_coordinates>
      <surface_model>EARTH_WGS84</surface_model>
      <latitude_deg>0</latitude_deg>
      <longitude_deg>0</longitude_deg>
      <elevation>0</elevation>
      <heading_deg>0</heading_deg>
    </spherical_coordinates>
    <model name='major'>
      <link name='base_link'>
        <pose frame=''>0 0 0 0 -0 0</pose>
        <inertial>
          <pose frame=''>0 2e-06 0.057146 0 -0 0</pose>
          <mass>1.125</mass>
          <inertia>
            <ixx>0.003</ixx>
            <ixy>-2.182e-09</ixy>
            <ixz>-3.604e-09</ixz>
            <iyy>0.003</iyy>
            <iyz>-2.052e-07</iyz>
            <izz>0.003</izz>
          </inertia>
        </inertial>
        <collision name='base_link_collision'>
          <pose frame=''>0 0 0 0 -0 0</pose>
          <geometry>
            <mesh>
              <scale>0.0254 0.0254 0.0254</scale>
              <uri>/home/sanchit/catkin_ws/src/major_project/meshes/base.stl</uri>
            </mesh>
          </geometry>
          <max_contacts>10</max_contacts>
          <surface>
            <contact>
              <ode/>
            </contact>
            <bounce/>
            <friction>
              <torsional>
                <ode/>
              </torsional>
              <ode/>
            </friction>
          </surface>
        </collision>
        <visual name='base_link_visual'>
          <pose frame=''>0 0 0 0 -0 0</pose>
          <geometry>
            <mesh>
              <scale>0.0254 0.0254 0.0254</scale>
              <uri>/home/sanchit/catkin_ws/src/major_project/meshes/base.stl</uri>
            </mesh>
          </geometry>
        </visual>
        <self_collide>0</self_collide>
        <enable_wind>0</enable_wind>
        <kinematic>0</kinematic>
      </link>
      <joint name='fixed' type='fixed'>
        <child>base_link</child>
        <parent>world</parent>
      </joint>
      <link name='link01'>
        <pose frame=''>0 0 0.108 0 -0 0</pose>
        <inertial>
          <pose frame=''>0 -0.007177 0.088082 0 -0 0</pose>
          <mass>3.128</mass>
          <inertia>
            <ixx>0.01</ixx>
            <ixy>-9.085e-09</ixy>
            <ixz>-3.761e-08</ixz>
            <iyy>0.005</iyy>
            <iyz>-7.51e-05</iyz>
            <izz>0.009</izz>
          </inertia>
        </inertial>
        <collision name='link01_collision'>
          <pose frame=''>0 0 0 0 -0 0</pose>
          <geometry>
            <mesh>
              <scale>0.0254 0.0254 0.0254</scale>
              <uri>/home/sanchit/catkin_ws/src/major_project/meshes/L1.stl</uri>
            </mesh>
          </geometry>
          <max_contacts>10</max_contacts>
          <surface>
            <contact>
              <ode/>
            </contact>
            <bounce/>
            <friction>
              <torsional>
                <ode/>
              </torsional>
              <ode/>
            </friction>
          </surface>
        </collision>
        <visual name='link01_visual'>
          <pose frame=''>0 0 0 0 -0 0</pose>
          <geometry>
            <mesh>
              <scale>0.0254 0.0254 0.0254</scale>
              <uri>/home/sanchit/catkin_ws/src/major_project/meshes/L1.stl</uri>
            </mesh>
          </geometry>
        </visual>
        <self_collide>0</self_collide>
        <enable_wind>0</enable_wind>
        <kinematic>0</kinematic>
      </link>
      <joint name='j01' type='revolute'>
        <child>link01</child>
        <parent>base_link</parent>
        <axis>
          <xyz>0 0 1</xyz>
          <limit>
            <lower>-6.28319</lower>
            <upper>6.28319</upper>
            <effort>4.6</effort>
            <velocity>0.524</velocity>
          </limit>
          <dynamics>
            <spring_reference>0</spring_reference>
            <spring_stiffness>0</spring_stiffness>
          </dynamics>
          <use_parent_model_frame>1</use_parent_model_frame>
        </axis>
      </joint>
      <link name='link02'>
        <pose frame=''>0 -0.077 0.199 0 -0 0</pose>
        <inertial>
          <pose frame=''>-0 -0.068171 0.141278 0 -0 0</pose>
          <mass>1.057</mass>
          <inertia>
            <ixx>0.005</ixx>
            <ixy>3.867e-10</ixy>
            <ixz>3.117e-09</ixz>
            <iyy>0.004</iyy>
            <iyz>0.0004763</iyz>
            <izz>0.001</izz>
          </inertia>
        </inertial>
        <collision name='link02_collision'>
          <pose frame=''>0 0 0 0 -0 0</pose>
          <geometry>
            <mesh>
              <scale>0.0254 0.0254 0.0254</scale>
              <uri>/home/sanchit/catkin_ws/src/major_project/meshes/L2.stl</uri>
            </mesh>
          </geometry>
          <max_contacts>10</max_contacts>
          <surface>
            <contact>
              <ode/>
            </contact>
            <bounce/>
            <friction>
              <torsional>
                <ode/>
              </torsional>
              <ode/>
            </friction>
          </surface>
        </collision>
        <visual name='link02_visual'>
          <pose frame=''>0 0 0 0 -0 0</pose>
          <geometry>
            <mesh>
              <scale>0.0254 0.0254 0.0254</scale>
              <uri>/home/sanchit/catkin_ws/src/major_project/meshes/L2.stl</uri>
            </mesh>
          </geometry>
        </visual>
        <self_collide>0</self_collide>
        <enable_wind>0</enable_wind>
        <kinematic>0</kinematic>
      </link>
      <joint name='j02' type='revolute'>
        <child>link02</child>
        <parent>link01</parent>
        <axis>
          <xyz>0 1 0</xyz>
          <limit>
            <lower>-6.28319</lower>
            <upper>6.28319</upper>
            <effort>30</effort>
            <velocity>0.524</velocity>
          </limit>
          <dynamics>
            <spring_reference>0</spring_reference>
            <spring_stiffness>0</spring_stiffness>
          </dynamics>
          <use_parent_model_frame>1</use_parent_model_frame>
        </axis>
      </joint>
      <link name='link03'>
        <pose frame=''>0 -0.102 0.369 0 -0 0</pose>
        <inertial>
          <pose frame=''>0.014302 0.045721 -4e-06 0 -0 0</pose>
          <mass>0.575</mass>
          <inertia>
            <ixx>0.0003184</ixx>
            <ixy>-1.057e-05</ixy>
            <ixz>-1.209e-07</ixz>
            <iyy>0.0004816</iyy>
            <iyz>1.809e-08</iyz>
            <izz>0.0004997</izz>
          </inertia>
        </inertial>
        <collision name='link03_collision'>
          <pose frame=''>0 0 0 0 -0 0</pose>
          <geometry>
            <mesh>
              <scale>0.0254 0.0254 0.0254</scale>
              <uri>/home/sanchit/catkin_ws/src/major_project/meshes/L3.stl</uri>
            </mesh>
          </geometry>
          <max_contacts>10</max_contacts>
          <surface>
            <contact>
              <ode/>
            </contact>
            <bounce/>
            <friction>
              <torsional>
                <ode/>
              </torsional>
              <ode/>
            </friction>
          </surface>
        </collision>
        <visual name='link03_visual'>
          <pose frame=''>0 0 0 0 -0 0</pose>
          <geometry>
            <mesh>
              <scale>0.0254 0.0254 0.0254</scale>
              <uri>/home/sanchit/catkin_ws/src/major_project/meshes/L3.stl</uri>
            </mesh>
          </geometry>
        </visual>
        <self_collide>0</self_collide>
        <enable_wind>0</enable_wind>
        <kinematic>0</kinematic>
      </link>
      <joint name='j03' type='revolute'>
        <child>link03</child>
        <parent>link02</parent>
        <axis>
          <xyz>0 1 0</xyz>
          <limit>
            <lower>-6.28319</lower>
            <upper>6.28319</upper>
            <effort>8.2</effort>
            <velocity>0.524</velocity>
          </limit>
          <dynamics>
            <spring_reference>0</spring_reference>
            <spring_stiffness>0</spring_stiffness>
          </dynamics>
          <use_parent_model_frame>1</use_parent_model_frame>
        </axis>
      </joint>
      <link name='link04'>
        <pose frame=''>0.046 -0.055 0.369 0 -0 0</pose>
        <inertial>
          <pose frame=''>0.128524 -0.000232 1e-06 0 -0 0</pose>
          <mass>0.944</mass>
          <inertia>
            <ixx>0.001</ixx>
            <ixy>-2.561e-06</ixy>
            <ixz>-4.394e-08</ixz>
            <iyy>0.001</iyy>
            <iyz>6.085e-08</iyz>
            <izz>0.002</izz>
          </inertia>
        </inertial>
        <collision name='link04_collision'>
          <pose frame=''>0 0 0 0 -0 0</pose>
          <geometry>
            <mesh>
              <scale>0.0254 0.0254 0.0254</scale>
              <uri>/home/sanchit/catkin_ws/src/major_project/meshes/L4.stl</uri>
            </mesh>
          </geometry>
          <max_contacts>10</max_contacts>
          <surface>
            <contact>
              <ode/>
            </contact>
            <bounce/>
            <friction>
              <torsional>
                <ode/>
              </torsional>
              <ode/>
            </friction>
          </surface>
        </collision>
        <visual name='link04_visual'>
          <pose frame=''>0 0 0 0 -0 0</pose>
          <geometry>
            <mesh>
              <scale>0.0254 0.0254 0.0254</scale>
              <uri>/home/sanchit/catkin_ws/src/major_project/meshes/L4.stl</uri>
            </mesh>
          </geometry>
        </visual>
        <self_collide>0</self_collide>
        <enable_wind>0</enable_wind>
        <kinematic>0</kinematic>
      </link>
      <joint name='j04' type='revolute'>
        <child>link04</child>
        <parent>link03</parent>
        <axis>
          <xyz>1 0 0</xyz>
          <limit>
            <lower>-6.28319</lower>
            <upper>6.28319</upper>
            <effort>1</effort>
            <velocity>0.524</velocity>
          </limit>
          <dynamics>
            <spring_reference>0</spring_reference>
            <spring_stiffness>0</spring_stiffness>
          </dynamics>
          <use_parent_model_frame>1</use_parent_model_frame>
        </axis>
      </joint>
      <link name='link05'>
        <pose frame=''>0.186 -0.009 0.369 0 -0 0</pose>
        <inertial>
          <pose frame=''>7e-06 0.045285 -0.016426 0 -0 0</pose>
          <mass>0.43</mass>
          <inertia>
            <ixx>0.0003708</ixx>
            <ixy>6.918e-09</ixy>
            <ixz>-1.392e-08</ixz>
            <iyy>0.000353</iyy>
            <iyz>1.212e-05</iyz>
            <izz>0.0002506</izz>
          </inertia>
        </inertial>
        <collision name='link05_collision'>
          <pose frame=''>0 0 0 0 -0 0</pose>
          <geometry>
            <mesh>
              <scale>0.0254 0.0254 0.0254</scale>
              <uri>/home/sanchit/catkin_ws/src/major_project/meshes/L5.stl</uri>
            </mesh>
          </geometry>
          <max_contacts>10</max_contacts>
          <surface>
            <contact>
              <ode/>
            </contact>
            <bounce/>
            <friction>
              <torsional>
                <ode/>
              </torsional>
              <ode/>
            </friction>
          </surface>
        </collision>
        <visual name='link05_visual'>
          <pose frame=''>0 0 0 0 -0 0</pose>
          <geometry>
            <mesh>
              <scale>0.0254 0.0254 0.0254</scale>
              <uri>/home/sanchit/catkin_ws/src/major_project/meshes/L5.stl</uri>
            </mesh>
          </geometry>
        </visual>
        <self_collide>0</self_collide>
        <enable_wind>0</enable_wind>
        <kinematic>0</kinematic>
      </link>
      <joint name='j05' type='revolute'>
        <child>link05</child>
        <parent>link04</parent>
        <axis>
          <xyz>0 1 0</xyz>
          <limit>
            <lower>-6.28319</lower>
            <upper>6.28319</upper>
            <effort>4.6</effort>
            <velocity>0.524</velocity>
          </limit>
          <dynamics>
            <spring_reference>0</spring_reference>
            <spring_stiffness>0</spring_stiffness>
          </dynamics>
          <use_parent_model_frame>1</use_parent_model_frame>
        </axis>
      </joint>
      <link name='link06'>
        <pose frame=''>0.186 0.038 0.322 0 -0 0</pose>
        <inertial>
          <pose frame=''>0 0 0 0 -0 0</pose>
          <mass>0.383</mass>
          <inertia>
            <ixx>0.001</ixx>
            <ixy>1.93e-07</ixy>
            <ixz>-0.0001128</ixz>
            <iyy>0.002</iyy>
            <iyz>6.562e-07</iyz>
            <izz>0.0001336</izz>
          </inertia>
        </inertial>
        <collision name='link06_collision'>
          <pose frame=''>0 0 0 0 -0 0</pose>
          <geometry>
            <mesh>
              <scale>1 1 1</scale>
              <uri>/home/sanchit/catkin_ws/src/major_project/meshes/end.stl</uri>
            </mesh>
          </geometry>
          <max_contacts>10</max_contacts>
          <surface>
            <contact>
              <ode/>
            </contact>
            <bounce/>
            <friction>
              <torsional>
                <ode/>
              </torsional>
              <ode/>
            </friction>
          </surface>
        </collision>
        <visual name='link06_visual'>
          <pose frame=''>0 0 0 0 -0 0</pose>
          <geometry>
            <mesh>
              <scale>1 1 1</scale>
              <uri>/home/sanchit/catkin_ws/src/major_project/meshes/end.stl</uri>
            </mesh>
          </geometry>
        </visual>
        <self_collide>0</self_collide>
        <enable_wind>0</enable_wind>
        <kinematic>0</kinematic>
      </link>
      <joint name='j06' type='revolute'>
        <child>link06</child>
        <parent>link05</parent>
        <axis>
          <xyz>0 0 1</xyz>
          <limit>
            <lower>-6.28319</lower>
            <upper>6.28319</upper>
            <effort>0.22</effort>
            <velocity>0.524</velocity>
          </limit>
          <dynamics>
            <spring_reference>0</spring_reference>
            <spring_stiffness>0</spring_stiffness>
          </dynamics>
          <use_parent_model_frame>1</use_parent_model_frame>
        </axis>
      </joint>
      <static>0</static>
      <plugin name='gazebo_ros_control' filename='libgazebo_ros_control.so'>
        <robotSimType>gazebo_ros_control/DefaultRobotHWSim</robotSimType>
        <robotNamespace>/</robotNamespace>
      </plugin>
      <pose frame=''>0 0 0 0 -0 0</pose>
    </model>
    <model name='unit_box_clone'>
      <link name='link'>
        <inertial>
          <mass>1</mass>
          <inertia>
            <ixx>0.166667</ixx>
            <ixy>0</ixy>
            <ixz>0</ixz>
            <iyy>0.166667</iyy>
            <iyz>0</iyz>
            <izz>0.166667</izz>
          </inertia>
          <pose frame=''>0 0 0 0 -0 0</pose>
        </inertial>
        <self_collide>0</self_collide>
        <enable_wind>0</enable_wind>
        <kinematic>0</kinematic>
        <pose frame=''>0 0 0 0 -0 0</pose>
        <gravity>1</gravity>
        <visual name='visual'>
          <geometry>
            <box>
              <size>0.226137 0.064342 0.02062</size>
            </box>
          </geometry>
          <material>
            <script>
              <name>Gazebo/Grey</name>
              <uri>file://media/materials/scripts/gazebo.material</uri>
            </script>
            <shader type='vertex'>
              <normal_map>__default__</normal_map>
            </shader>
            <ambient>1 0 0 1</ambient>
            <diffuse>1 0 0 1</diffuse>
            <specular>0.1 0.1 0.1 1</specular>
            <emissive>0 0 0 1</emissive>
          </material>
          <pose frame=''>0 0 0 0 -0 0</pose>
          <transparency>0</transparency>
          <cast_shadows>1</cast_shadows>
        </visual>
        <collision name='collision'>
          <laser_retro>0</laser_retro>
          <max_contacts>10</max_contacts>
          <pose frame=''>0 0 0 0 -0 0</pose>
          <geometry>
            <box>
              <size>0.226137 0.064342 0.02062</size>
            </box>
          </geometry>
          <surface>
            <friction>
              <ode>
                <mu>1</mu>
                <mu2>1</mu2>
                <fdir1>0 0 0</fdir1>
                <slip1>0</slip1>
                <slip2>0</slip2>
              </ode>
              <torsional>
                <coefficient>1</coefficient>
                <patch_radius>0</patch_radius>
                <surface_radius>0</surface_radius>
                <use_patch_radius>1</use_patch_radius>
                <ode>
                  <slip>0</slip>
                </ode>
              </torsional>
            </friction>
            <bounce>
              <restitution_coefficient>0</restitution_coefficient>
              <threshold>1e+06</threshold>
            </bounce>
            <contact>
              <collide_without_contact>0</collide_without_contact>
              <collide_without_contact_bitmask>1</collide_without_contact_bitmask>
              <collide_bitmask>1</collide_bitmask>
              <ode>
                <soft_cfm>0</soft_cfm>
                <soft_erp>0.2</soft_erp>
                <kp>1e+13</kp>
                <kd>1</kd>
                <max_vel>0.01</max_vel>
                <min_depth>0</min_depth>
              </ode>
              <bullet>
                <split_impulse>1</split_impulse>
                <split_impulse_penetration_threshold>-0.01</split_impulse_penetration_threshold>
                <soft_cfm>0</soft_cfm>
                <soft_erp>0.2</soft_erp>
                <kp>1e+13</kp>
                <kd>1</kd>
              </bullet>
            </contact>
          </surface>
        </collision>
      </link>
      <static>1</static>
      <allow_auto_disable>1</allow_auto_disable>
      <pose frame=''>0.249508 -0.012816 0 0 -0 0</pose>
    </model>
    <model name='unit_box_clone_0'>
      <link name='link'>
        <inertial>
          <mass>1</mass>
          <inertia>
            <ixx>0.166667</ixx>
            <ixy>0</ixy>
            <ixz>0</ixz>
            <iyy>0.166667</iyy>
            <iyz>0</iyz>
            <izz>0.166667</izz>
          </inertia>
          <pose frame=''>0 0 0 0 -0 0</pose>
        </inertial>
        <self_collide>0</self_collide>
        <enable_wind>0</enable_wind>
        <kinematic>0</kinematic>
        <pose frame=''>0 0 0 0 -0 0</pose>
        <gravity>1</gravity>
        <visual name='visual'>
          <geometry>
            <box>
              <size>0.226137 0.064342 0.02062</size>
            </box>
          </geometry>
          <material>
            <script>
              <name>Gazebo/Grey</name>
              <uri>file://media/materials/scripts/gazebo.material</uri>
            </script>
            <shader type='vertex'>
              <normal_map>__default__</normal_map>
            </shader>
            <ambient>1 0 0 1</ambient>
            <diffuse>1 0 0 1</diffuse>
            <specular>0.1 0.1 0.1 1</specular>
            <emissive>0 0 0 1</emissive>
          </material>
          <pose frame=''>0 0 0 0 -0 0</pose>
          <transparency>0</transparency>
          <cast_shadows>1</cast_shadows>
        </visual>
        <collision name='collision'>
          <laser_retro>0</laser_retro>
          <max_contacts>10</max_contacts>
          <pose frame=''>0 0 0 0 -0 0</pose>
          <geometry>
            <box>
              <size>0.226137 0.064342 0.02062</size>
            </box>
          </geometry>
          <surface>
            <friction>
              <ode>
                <mu>1</mu>
                <mu2>1</mu2>
                <fdir1>0 0 0</fdir1>
                <slip1>0</slip1>
                <slip2>0</slip2>
              </ode>
              <torsional>
                <coefficient>1</coefficient>
                <patch_radius>0</patch_radius>
                <surface_radius>0</surface_radius>
                <use_patch_radius>1</use_patch_radius>
                <ode>
                  <slip>0</slip>
                </ode>
              </torsional>
            </friction>
            <bounce>
              <restitution_coefficient>0</restitution_coefficient>
              <threshold>1e+06</threshold>
            </bounce>
            <contact>
              <collide_without_contact>0</collide_without_contact>
              <collide_without_contact_bitmask>1</collide_without_contact_bitmask>
              <collide_bitmask>1</collide_bitmask>
              <ode>
                <soft_cfm>0</soft_cfm>
                <soft_erp>0.2</soft_erp>
                <kp>1e+13</kp>
                <kd>1</kd>
                <max_vel>0.01</max_vel>
                <min_depth>0</min_depth>
              </ode>
              <bullet>
                <split_impulse>1</split_impulse>
                <split_impulse_penetration_threshold>-0.01</split_impulse_penetration_threshold>
                <soft_cfm>0</soft_cfm>
                <soft_erp>0.2</soft_erp>
                <kp>1e+13</kp>
                <kd>1</kd>
              </bullet>
            </contact>
          </surface>
        </collision>
      </link>
      <static>1</static>
      <allow_auto_disable>1</allow_auto_disable>
      <pose frame=''>0.250272 0.062806 0 0 -0 0</pose>
    </model>
    <state world_name='default'>
      <sim_time>156 842000000</sim_time>
      <real_time>291 172051785</real_time>
      <wall_time>1618843984 95907656</wall_time>
      <iterations>156842</iterations>
      <model name='ground_plane'>
        <pose frame=''>0 0 0 0 -0 0</pose>
        <scale>1 1 1</scale>
        <link name='link'>
          <pose frame=''>0 0 0 0 -0 0</pose>
          <velocity>0 0 0 0 -0 0</velocity>
          <acceleration>0 0 0 0 -0 0</acceleration>
          <wrench>0 0 0 0 -0 0</wrench>
        </link>
      </model>
      <model name='major'>
        <pose frame=''>0 -0 0 0 -5e-06 -2e-06</pose>
        <scale>1 1 1</scale>
        <link name='base_link'>
          <pose frame=''>0 -0 0 0 -5e-06 -2e-06</pose>
          <velocity>8e-06 2.1e-05 1.1e-05 0.00055 -2.8e-05 0.000189</velocity>
          <acceleration>-0.035629 0.0411 -0.043881 -0.453152 -0.693251 0.117342</acceleration>
          <wrench>-0.040083 0.046237 -0.049366 0 -0 0</wrench>
        </link>
        <link name='link01'>
          <pose frame=''>2e-06 -1e-06 0.108 1.4e-05 2.8e-05 1.9e-05</pose>
          <velocity>5e-06 -3.8e-05 1.1e-05 0.000704 -1.4e-05 0.000456</velocity>
          <acceleration>-0.034386 0.037093 -0.047175 -0.119346 -0.316581 0.181082</acceleration>
          <wrench>-0.107559 0.116027 -0.147563 0 -0 0</wrench>
        </link>
        <link name='link02'>
          <pose frame=''>1e-05 -0.076999 0.198999 1.9e-05 4.3e-05 3.6e-05</pose>
          <velocity>6e-05 -0.000101 -4.3e-05 0.000702 0.002505 0.000394</velocity>
          <acceleration>0.013678 0.0086 -0.059732 -0.036634 -0.184913 0.48066</acceleration>
          <wrench>0.014458 0.00909 -0.063137 0 -0 0</wrench>
        </link>
        <link name='link03'>
          <pose frame=''>1.9e-05 -0.102003 0.368986 4.1e-05 4.4e-05 3.7e-05</pose>
          <velocity>0.000464 -0.00021 -4.7e-05 0.000654 -0.004764 0.000532</velocity>
          <acceleration>0.042651 -0.011157 -0.045615 -0.081003 -0.070082 0.01171</acceleration>
          <wrench>0.024524 -0.006415 -0.026229 0 -0 0</wrench>
        </link>
        <link name='link04'>
          <pose frame=''>0.046017 -0.055001 0.368974 0.000121 0.000224 3.6e-05</pose>
          <velocity>0.000439 -0.000167 0.000207 -0.011747 -0.004847 0.001037</velocity>
          <acceleration>0.050193 -0.068969 -0.033733 0.212186 -0.072648 -0.321751</acceleration>
          <wrench>0.047382 -0.065107 -0.031844 0 -0 0</wrench>
        </link>
        <link name='link05'>
          <pose frame=''>0.186015 -0.008996 0.368946 0.000103 0.000237 3.7e-05</pose>
          <velocity>0.000388 -2e-05 0.000352 -0.011722 -0.003708 0.001049</velocity>
          <acceleration>0.087998 -0.067415 0.000231 0.290796 -0.079501 -0.305776</acceleration>
          <wrench>0.037839 -0.028989 9.9e-05 0 -0 0</wrench>
        </link>
        <link name='link06'>
          <pose frame=''>0.186002 0.038009 0.32195 0.000102 0.000247 3.1e-05</pose>
          <velocity>0.000511 -0.000568 -0.000199 -0.011677 -0.00369 0.001025</velocity>
          <acceleration>0.092966 -0.057926 0.002471 0.366982 -0.082284 -0.289668</acceleration>
          <wrench>0.035606 -0.022186 0.000946 0 -0 0</wrench>
        </link>
      </model>
      <model name='unit_box_clone'>
        <pose frame=''>0.273474 0.001873 0 0 -0 0</pose>
        <scale>1 1 1</scale>
        <link name='link'>
          <pose frame=''>0.273474 0.001873 0 0 -0 0</pose>
          <velocity>0 0 0 0 -0 0</velocity>
          <acceleration>0 0 0 0 -0 0</acceleration>
          <wrench>0 0 0 0 -0 0</wrench>
        </link>
      </model>
      <model name='unit_box_clone_0'>
        <pose frame=''>0.273536 0.069257 0 0 -0 0</pose>
        <scale>1 1 1</scale>
        <link name='link'>
          <pose frame=''>0.273536 0.069257 0 0 -0 0</pose>
          <velocity>0 0 0 0 -0 0</velocity>
          <acceleration>0 0 0 0 -0 0</acceleration>
          <wrench>0 0 0 0 -0 0</wrench>
        </link>
      </model>
      <light name='sun'>
        <pose frame=''>0 0 10 0 -0 0</pose>
      </light>
    </state>
    <gui fullscreen='0'>
      <camera name='user_camera'>
        <pose frame=''>0.516223 -1.18389 0.577194 0 0.291643 1.89619</pose>
        <view_controller>orbit</view_controller>
        <projection_type>perspective</projection_type>
      </camera>
    </gui>
  </world>
</sdf>
