<?xml version="1.0" encoding="utf-8"?>
<!-- =================================================================================== -->
<!-- |    This document was autogenerated by xacro from welding.xacro                  | -->
<!-- |    EDITING THIS FILE BY HAND IS NOT RECOMMENDED                                 | -->
<!-- =================================================================================== -->
<robot name="major">
  <create/>
  <link name="world"/>
  <joint name="fixed" type="fixed">
    <parent link="world"/>
    <child link="base_link"/>
  </joint>
  <link name="base_link">
    <inertial>
      <mass value="1.125"/>
      <origin rpy="0 0 0" xyz="0.00000006956 0.000001763 0.0571457831331258"/>
      <inertia ixx="0.003" ixy="-2.182e-09" ixz="-3.604e-09" iyy="0.003" iyz="-2.052e-07" izz="0.003"/>
    </inertial>
    <collision>
      <origin rpy="0 0 0" xyz="0 0 0"/>
      <geometry>
        <mesh filename="package://major_project/meshes/base.stl" scale="0.0254 0.0254 0.0254"/>
      </geometry>
    </collision>
    <visual>
      <origin rpy="0 0 0" xyz="0 0 0"/>
      <geometry>
        <mesh filename="package://major_project/meshes/base.stl" scale="0.0254 0.0254 0.0254"/>
      </geometry>
    </visual>
  </link>
  <joint name="j01" type="revolute">
    <axis xyz="0 0 1"/>
    <limit effort="4.6" lower="-6.283185307" upper="6.283185307" velocity="0.524"/>
    <origin rpy="0 0 0" xyz="0 0 0.108"/>
    <parent link="base_link"/>
    <child link="link01"/>
  </joint>
  <transmission name="trans_j01">
    <type>transmission_interface/SimpleTransmission</type>
    <joint name="j01">
      <hardwareInterface>hardware_interface/PositionJointInterface</hardwareInterface>
    </joint>
    <actuator name="motor_j01">
      <hardwareInterface>hardware_interface/PositionJointInterface</hardwareInterface>
      <mechanicalReduction>1</mechanicalReduction>
    </actuator>
  </transmission>
  <link name="link01">
    <inertial>
      <mass value="3.128"/>
      <origin rpy="0 0 0" xyz="0.0000003253 -0.0071769588574323 0.0880824299338031"/>
      <inertia ixx="0.01" ixy="-9.085e-09" ixz="-3.761e-08" iyy="0.005" iyz="-7.51e-05" izz="0.009"/>
    </inertial>
    <collision>
      <origin rpy="0 0 0" xyz="0 0 0"/>
      <geometry>
        <mesh filename="package://major_project/meshes/L1.stl" scale="0.0254 0.0254 0.0254"/>
      </geometry>
    </collision>
    <visual>
      <origin rpy="0 0 0" xyz="0 0 0"/>
      <geometry>
        <mesh filename="package://major_project/meshes/L1.stl" scale="0.0254 0.0254 0.0254"/>
      </geometry>
    </visual>
  </link>
  <joint name="j02" type="revolute">
    <axis xyz="0 1 0"/>
    <limit effort="30" lower="-6.283185307" upper="6.283185307" velocity="0.524"/>
    <origin rpy="0 0 0" xyz="0 -0.077 0.091"/>
    <parent link="link01"/>
    <child link="link02"/>
  </joint>
  <transmission name="trans_j02">
    <type>transmission_interface/SimpleTransmission</type>
    <joint name="j02">
      <hardwareInterface>hardware_interface/PositionJointInterface</hardwareInterface>
    </joint>
    <actuator name="motor_j02">
      <hardwareInterface>hardware_interface/PositionJointInterface</hardwareInterface>
      <mechanicalReduction>1</mechanicalReduction>
    </actuator>
  </transmission>
  <link name="link02">
    <inertial>
      <mass value="1.057"/>
      <origin rpy="0 0 0" xyz="-0.00000001292 -0.0681708395054807 0.1412776907479262"/>
      <inertia ixx="0.005" ixy="3.867e-10" ixz="3.117e-09" iyy="0.004" iyz="0.0004763" izz="0.001"/>
    </inertial>
    <collision>
      <origin rpy="0 0 0" xyz="0 0 0"/>
      <geometry>
        <mesh filename="package://major_project/meshes/L2.stl" scale="0.0254 0.0254 0.0254"/>
      </geometry>
    </collision>
    <visual>
      <origin rpy="0 0 0" xyz="0 0 0"/>
      <geometry>
        <mesh filename="package://major_project/meshes/L2.stl" scale="0.0254 0.0254 0.0254"/>
      </geometry>
    </visual>
  </link>
  <joint name="j03" type="revolute">
    <axis xyz="0 1 0"/>
    <limit effort="8.2" lower="-6.283185307" upper="6.283185307" velocity="0.524"/>
    <origin rpy="0 0 0" xyz="0 -0.025 0.17"/>
    <parent link="link02"/>
    <child link="link03"/>
  </joint>
  <transmission name="trans_j03">
    <type>transmission_interface/SimpleTransmission</type>
    <joint name="j03">
      <hardwareInterface>hardware_interface/PositionJointInterface</hardwareInterface>
    </joint>
    <actuator name="motor_j03">
      <hardwareInterface>hardware_interface/PositionJointInterface</hardwareInterface>
      <mechanicalReduction>1</mechanicalReduction>
    </actuator>
  </transmission>
  <link name="link03">
    <inertial>
      <mass value="0.575"/>
      <origin rpy="0 0 0" xyz="0.014302060949178 0.0457204972120587 -0.000003751"/>
      <inertia ixx="0.0003184" ixy="-1.057e-05" ixz="-1.209e-07" iyy="0.0004816" iyz="1.809e-08" izz="0.0004997"/>
    </inertial>
    <collision>
      <origin rpy="0 0 0" xyz="0 0 0"/>
      <geometry>
        <mesh filename="package://major_project/meshes/L3.stl" scale="0.0254 0.0254 0.0254"/>
      </geometry>
    </collision>
    <visual>
      <origin rpy="0 0 0" xyz="0 0 0"/>
      <geometry>
        <mesh filename="package://major_project/meshes/L3.stl" scale="0.0254 0.0254 0.0254"/>
      </geometry>
    </visual>
  </link>
  <joint name="j04" type="revolute">
    <axis xyz="1 0 0"/>
    <limit effort="1.0" lower="-6.283185307" upper="6.283185307" velocity="0.524"/>
    <origin rpy="0 0 0" xyz="0.046 0.047 0"/>
    <parent link="link03"/>
    <child link="link04"/>
  </joint>
  <transmission name="trans_j04">
    <type>transmission_interface/SimpleTransmission</type>
    <joint name="j04">
      <hardwareInterface>hardware_interface/PositionJointInterface</hardwareInterface>
    </joint>
    <actuator name="motor_j04">
      <hardwareInterface>hardware_interface/PositionJointInterface</hardwareInterface>
      <mechanicalReduction>1</mechanicalReduction>
    </actuator>
  </transmission>
  <link name="link04">
    <inertial>
      <mass value="0.944"/>
      <origin rpy="0 0 0" xyz="0.1285235708972777 -0.0002318 0.0000009316 "/>
      <inertia ixx="0.001" ixy="-2.561e-06" ixz="-4.394e-08" iyy="0.001" iyz="6.085e-08" izz="0.002"/>
    </inertial>
    <collision>
      <origin rpy="0 0 0" xyz="0 0 0"/>
      <geometry>
        <mesh filename="package://major_project/meshes/L4.stl" scale="0.0254 0.0254 0.0254"/>
      </geometry>
    </collision>
    <visual>
      <origin rpy="0 0 0" xyz="0 0 0"/>
      <geometry>
        <mesh filename="package://major_project/meshes/L4.stl" scale="0.0254 0.0254 0.0254"/>
      </geometry>
    </visual>
  </link>
  <joint name="j05" type="revolute">
    <axis xyz="0 1 0"/>
    <limit effort="4.6" lower="-6.283185307" upper="6.283185307" velocity="0.524"/>
    <origin rpy="0 0 0" xyz="0.14 0.046 0"/>
    <parent link="link04"/>
    <child link="link05"/>
  </joint>
  <transmission name="trans_j05">
    <type>transmission_interface/SimpleTransmission</type>
    <joint name="j05">
      <hardwareInterface>hardware_interface/PositionJointInterface</hardwareInterface>
    </joint>
    <actuator name="motor_j05">
      <hardwareInterface>hardware_interface/PositionJointInterface</hardwareInterface>
      <mechanicalReduction>1</mechanicalReduction>
    </actuator>
  </transmission>
  <link name="link05">
    <inertial>
      <mass value="0.43"/>
      <origin rpy="0 0 0" xyz="0.000007270 0.0452851526908512 -0.016426322544385"/>
      <inertia ixx="0.0003708" ixy="6.918e-09" ixz="-1.392e-08" iyy="0.000353" iyz="1.212e-05" izz="0.0002506"/>
    </inertial>
    <collision>
      <origin rpy="0 0 0" xyz="0 0 0"/>
      <geometry>
        <mesh filename="package://major_project/meshes/L5.stl" scale="0.0254 0.0254 0.0254"/>
      </geometry>
    </collision>
    <visual>
      <origin rpy="0 0 0" xyz="0 0 0"/>
      <geometry>
        <mesh filename="package://major_project/meshes/L5.stl" scale="0.0254 0.0254 0.0254"/>
      </geometry>
    </visual>
  </link>
  <joint name="j06" type="revolute">
    <axis xyz="0 0 1"/>
    <limit effort="0.22" lower="-6.283185307" upper="6.283185307" velocity="0.524"/>
    <origin rpy="0 0 0" xyz="0 0.047 -0.047"/>
    <parent link="link05"/>
    <child link="link06"/>
  </joint>
  <transmission name="trans_j06">
    <type>transmission_interface/SimpleTransmission</type>
    <joint name="j06">
      <hardwareInterface>hardware_interface/PositionJointInterface</hardwareInterface>
    </joint>
    <actuator name="motor_j06">
      <hardwareInterface>hardware_interface/PositionJointInterface</hardwareInterface>
      <mechanicalReduction>1</mechanicalReduction>
    </actuator>
  </transmission>
  <link name="link06">
    <inertial>
      <mass value="0.383"/>
      <origin rpy="0 0 0" xyz="0 0 0"/>
      <inertia ixx="0.001" ixy="1.93e-07" ixz="-0.0001128" iyy="0.002" iyz="6.562e-07" izz="0.0001336"/>
    </inertial>
    <collision>
      <origin rpy="0 0 0" xyz="0 0 0"/>
      <geometry>
        <mesh filename="package://major_project/meshes/end.stl" scale="1 1 1"/>
      </geometry>
    </collision>
    <visual>
      <origin rpy="0 0 0" xyz="0 0 0"/>
      <geometry>
        <mesh filename="package://major_project/meshes/end.stl" scale="1 1 1"/>
      </geometry>
    </visual>
  </link>
  <gazebo>
    <plugin filename="libgazebo_ros_control.so" name="gazebo_ros_control">
      <robotSimType>gazebo_ros_control/DefaultRobotHWSim</robotSimType>
    </plugin>
  </gazebo>
</robot>
